Traceback (most recent call last):
  File "C:/Users/nicho/Desktop/PythonPrograms/Unit_Debugging/Raise_assert_Statements.py", line 10, in <module>
    raise Exception('This is the error message.')
Exception: This is the error message.
Traceback (most recent call last):
  File "C:/Users/nicho/Desktop/PythonPrograms/Unit_Debugging/Raise_assert_Statements.py", line 10, in <module>
    raise Exception('This is the error message.')
Exception: This is the error message.
